<?xml version="1.0" encoding="utf-8"?>
<!-- Marvin left arm (7-DOF). Originally generated by SolidWorks to URDF Exporter.
     Refactored from M6-S-L-CCS-696-V4.urdf.xacro.
     Commit Version: 1.5.1-0-g916b5db  Build Version: 1.5.7152.31018
     For more information, please see http://wiki.ros.org/sw_urdf_exporter -->
<robot xmlns:xacro="http://ros.org/wiki/xacro">
  <xacro:macro name="marvin_left_arm"
    params="parent:=base_link xyz:='0 0 0' rpy:='0 0 0' description_pkg:=marvin_description">

    <!-- Mounting joint from parent (typically base_link) to Base_L -->
    <joint name="base_to_left_arm" type="fixed">
      <parent link="${parent}"/>
      <child link="Base_L"/>
      <origin xyz="${xyz}" rpy="${rpy}"/>
    </joint>

    <link
      name="Base_L">
      <xacro:marvin_link_inertial key="base"/>
      <visual>
        <origin
          xyz="0 0 0"
          rpy="0 0 0" />
        <geometry>
          <mesh
            filename="package://${description_pkg}/meshes/m6/Base_L.STL" />
        </geometry>
        <material name="red_L">
          <color rgba="1 0 0 1" />
        </material>
      </visual>
      <collision>
        <origin
          xyz="0 0 0"
          rpy="0 0 0" />
        <geometry>
          <mesh
            filename="package://${description_pkg}/meshes/m6/Base_L.STL" />
        </geometry>
      </collision>
    </link>
    <link
      name="Link1_L">
      <xacro:marvin_link_inertial key="link1"/>
      <visual>
        <origin
          xyz="0 0 0"
          rpy="0 0 0" />
        <geometry>
          <mesh
            filename="package://${description_pkg}/meshes/m6/Link1_L.STL" />
        </geometry>
        <material name="green_L">
          <color rgba="0 1 0 1" />
        </material>
      </visual>
      <collision>
        <origin
          xyz="0 0 0"
          rpy="0 0 0" />
        <geometry>
          <mesh
            filename="package://${description_pkg}/meshes/m6/Link1_L.STL" />
        </geometry>
      </collision>
    </link>
    <joint
      name="Joint1_L"
      type="revolute">
      <xacro:marvin_joint_parameters key="joint1"/>

      <parent
        link="Base_L" />
      <child
        link="Link1_L" />


    </joint>
    <link
      name="Link2_L">
      <xacro:marvin_link_inertial key="link2"/>
      <visual>
        <origin
          xyz="0 0 0"
          rpy="0 0 0" />
        <geometry>
          <mesh
            filename="package://${description_pkg}/meshes/m6/Link2_L.STL" />
        </geometry>
        <material name="blue_L">
          <color rgba="0 0 1 1" />
        </material>
      </visual>
      <collision>
        <origin
          xyz="0 0 0"
          rpy="0 0 0" />
        <geometry>
          <mesh
            filename="package://${description_pkg}/meshes/m6/Link2_L.STL" />
        </geometry>
      </collision>
    </link>
    <joint
      name="Joint2_L"
      type="revolute">
      <xacro:marvin_joint_parameters key="joint2"/>

      <parent
        link="Link1_L" />
      <child
        link="Link2_L" />


    </joint>
    <link
      name="Link3_L">
      <xacro:marvin_link_inertial key="link3"/>
      <visual>
        <origin
          xyz="0 0 0"
          rpy="0 0 0" />
        <geometry>
          <mesh
            filename="package://${description_pkg}/meshes/m6/Link3_L.STL" />
        </geometry>
        <material name="red_L" />
      </visual>
      <collision>
        <origin
          xyz="0 0 0"
          rpy="0 0 0" />
        <geometry>
          <mesh
            filename="package://${description_pkg}/meshes/m6/Link3_L.STL" />
        </geometry>
      </collision>
    </link>
    <joint
      name="Joint3_L"
      type="revolute">
      <xacro:marvin_joint_parameters key="joint3"/>

      <parent
        link="Link2_L" />
      <child
        link="Link3_L" />


    </joint>
    <link
      name="Link4_L">
      <xacro:marvin_link_inertial key="link4"/>
      <visual>
        <origin
          xyz="0 0 0"
          rpy="0 0 0" />
        <geometry>
          <mesh
            filename="package://${description_pkg}/meshes/m6/Link4_L.STL" />
        </geometry>
        <material name="green_L" />
      </visual>
      <collision>
        <origin
          xyz="0 0 0"
          rpy="0 0 0" />
        <geometry>
          <mesh
            filename="package://${description_pkg}/meshes/m6/Link4_L.STL" />
        </geometry>
      </collision>
    </link>
    <joint
      name="Joint4_L"
      type="revolute">
      <xacro:marvin_joint_parameters key="joint4"/>

      <parent
        link="Link3_L" />
      <child
        link="Link4_L" />


    </joint>
    <link
      name="Link5_L">
      <xacro:marvin_link_inertial key="link5_left"/>
      <visual>
        <origin
          xyz="0 0 0"
          rpy="0 0 0" />
        <geometry>
          <mesh
            filename="package://${description_pkg}/meshes/m6/Link5_L.STL" />
        </geometry>
        <material name="blue_L" />
      </visual>
      <collision>
        <origin
          xyz="0 0 0"
          rpy="0 0 0" />
        <geometry>
          <mesh
            filename="package://${description_pkg}/meshes/m6/Link5_L.STL" />
        </geometry>
      </collision>
    </link>
    <joint
      name="Joint5_L"
      type="revolute">
      <xacro:marvin_joint_parameters key="joint5"/>

      <parent
        link="Link4_L" />
      <child
        link="Link5_L" />


    </joint>
    <link
      name="Link6_L">
      <xacro:marvin_link_inertial key="link6_left"/>
      <visual>
        <origin
          xyz="0 0 0"
          rpy="0 0 0" />
        <geometry>
          <mesh
            filename="package://${description_pkg}/meshes/m6/Link6_L.STL" />
        </geometry>
        <material name="red_L" />
      </visual>
      <collision>
        <origin
          xyz="0 0 0"
          rpy="0 0 0" />
        <geometry>
          <mesh
            filename="package://${description_pkg}/meshes/m6/Link6_L.STL" />
        </geometry>
      </collision>
    </link>
    <joint
      name="Joint6_L"
      type="revolute">
      <xacro:marvin_joint_parameters key="joint6"/>

      <parent
        link="Link5_L" />
      <child
        link="Link6_L" />


    </joint>
    <link
      name="Link7_L">
      <xacro:marvin_link_inertial key="link7"/>
      <visual>
        <origin
          xyz="0 0 0"
          rpy="0 0 0" />
        <geometry>
          <mesh
            filename="package://${description_pkg}/meshes/m6/Link7_L.STL" />
        </geometry>
        <material name="green_L" />
      </visual>
      <collision>
        <origin
          xyz="0 0 0"
          rpy="0 0 0" />
        <geometry>
          <mesh
            filename="package://${description_pkg}/meshes/m6/Link7_L.STL" />
        </geometry>
      </collision>
    </link>
    <joint
      name="Joint7_L"
      type="revolute">
      <xacro:marvin_joint_parameters key="joint7"/>

      <parent
        link="Link6_L" />
      <child
        link="Link7_L" />


    </joint>
    <link name="flange_L"/>
    <joint name="joint_flange_L" type="fixed">
      <origin
        xyz="${marvin_kinematics['flange']['origin']['xyz']}"
        rpy="${marvin_kinematics['flange']['origin']['rpy']}"/>
      <parent link="Link7_L" />
      <child link="flange_L" />
    </joint>
  </xacro:macro>
</robot>
