<?xml version="1.0" encoding="utf-8"?>
<!-- Marvin right arm (7-DOF). Originally generated by SolidWorks to URDF Exporter.
     Refactored from M6-S-R-CCS-696-V4.urdf.xacro.
     Commit Version: 1.5.1-0-g916b5db  Build Version: 1.5.7152.31018
     For more information, please see http://wiki.ros.org/sw_urdf_exporter -->
<robot xmlns:xacro="http://ros.org/wiki/xacro">
  <xacro:macro name="marvin_right_arm"
    params="parent:=base_link xyz:='0 0 0' rpy:='0 0 0' description_pkg:=marvin_description">

    <!-- Mounting joint from parent (typically base_link) to Base_R -->
    <joint name="base_to_right_arm" type="fixed">
      <parent link="${parent}"/>
      <child link="Base_R"/>
      <origin xyz="${xyz}" rpy="${rpy}"/>
    </joint>

    <link
      name="Base_R">
      <xacro:marvin_link_inertial key="base"/>
      <visual>
        <origin
          xyz="0 0 0"
          rpy="0 0 0" />
        <geometry>
          <mesh
            filename="package://${description_pkg}/meshes/m6/Base_R.STL" />
        </geometry>
        <material name="red_R">
          <color rgba="1 0 0 1" />
        </material>
      </visual>
      <collision>
        <origin
          xyz="0 0 0"
          rpy="0 0 0" />
        <geometry>
          <mesh
            filename="package://${description_pkg}/meshes/m6/Base_R.STL" />
        </geometry>
      </collision>
    </link>
    <link
      name="Link1_R">
      <xacro:marvin_link_inertial key="link1"/>
      <visual>
        <origin
          xyz="0 0 0"
          rpy="0 0 0" />
        <geometry>
          <mesh
            filename="package://${description_pkg}/meshes/m6/Link1_R.STL" />
        </geometry>
        <material name="green_R">
          <color rgba="0 1 0 1" />
        </material>
      </visual>
      <collision>
        <origin
          xyz="0 0 0"
          rpy="0 0 0" />
        <geometry>
          <mesh
            filename="package://${description_pkg}/meshes/m6/Link1_R.STL" />
        </geometry>
      </collision>
    </link>
    <joint
      name="Joint1_R"
      type="revolute">
      <xacro:marvin_joint_parameters key="joint1"/>

      <parent
        link="Base_R" />
      <child
        link="Link1_R" />


    </joint>
    <link
      name="Link2_R">
      <xacro:marvin_link_inertial key="link2"/>
      <visual>
        <origin
          xyz="0 0 0"
          rpy="0 0 0" />
        <geometry>
          <mesh
            filename="package://${description_pkg}/meshes/m6/Link2_R.STL" />
        </geometry>
        <material name="blue_R">
          <color rgba="0 0 1 1" />
        </material>
      </visual>
      <collision>
        <origin
          xyz="0 0 0"
          rpy="0 0 0" />
        <geometry>
          <mesh
            filename="package://${description_pkg}/meshes/m6/Link2_R.STL" />
        </geometry>
      </collision>
    </link>
    <joint
      name="Joint2_R"
      type="revolute">
      <xacro:marvin_joint_parameters key="joint2"/>

      <parent
        link="Link1_R" />
      <child
        link="Link2_R" />


    </joint>
    <link
      name="Link3_R">
      <xacro:marvin_link_inertial key="link3"/>
      <visual>
        <origin
          xyz="0 0 0"
          rpy="0 0 0" />
        <geometry>
          <mesh
            filename="package://${description_pkg}/meshes/m6/Link3_R.STL" />
        </geometry>
        <material name="red_R" />
      </visual>
      <collision>
        <origin
          xyz="0 0 0"
          rpy="0 0 0" />
        <geometry>
          <mesh
            filename="package://${description_pkg}/meshes/m6/Link3_R.STL" />
        </geometry>
      </collision>
    </link>
    <joint
      name="Joint3_R"
      type="revolute">
      <xacro:marvin_joint_parameters key="joint3"/>

      <parent
        link="Link2_R" />
      <child
        link="Link3_R" />


    </joint>
    <link
      name="Link4_R">
      <xacro:marvin_link_inertial key="link4"/>
      <visual>
        <origin
          xyz="0 0 0"
          rpy="0 0 0" />
        <geometry>
          <mesh
            filename="package://${description_pkg}/meshes/m6/Link4_R.STL" />
        </geometry>
        <material name="green_R" />
      </visual>
      <collision>
        <origin
          xyz="0 0 0"
          rpy="0 0 0" />
        <geometry>
          <mesh
            filename="package://${description_pkg}/meshes/m6/Link4_R.STL" />
        </geometry>
      </collision>
    </link>
    <joint
      name="Joint4_R"
      type="revolute">
      <xacro:marvin_joint_parameters key="joint4"/>

      <parent
        link="Link3_R" />
      <child
        link="Link4_R" />


    </joint>
    <link
      name="Link5_R">
      <xacro:marvin_link_inertial key="link5_right"/>
      <visual>
        <origin
          xyz="0 0 0"
          rpy="0 0 0" />
        <geometry>
          <mesh
            filename="package://${description_pkg}/meshes/m6/Link5_R.STL" />
        </geometry>
        <material name="blue_R" />
      </visual>
      <collision>
        <origin
          xyz="0 0 0"
          rpy="0 0 0" />
        <geometry>
          <mesh
            filename="package://${description_pkg}/meshes/m6/Link5_R.STL" />
        </geometry>
      </collision>
    </link>
    <joint
      name="Joint5_R"
      type="revolute">
      <xacro:marvin_joint_parameters key="joint5"/>

      <parent
        link="Link4_R" />
      <child
        link="Link5_R" />


    </joint>
    <link
      name="Link6_R">
      <xacro:marvin_link_inertial key="link6_right"/>
      <visual>
        <origin
          xyz="0 0 0"
          rpy="0 0 0" />
        <geometry>
          <mesh
            filename="package://${description_pkg}/meshes/m6/Link6_R.STL" />
        </geometry>
        <material name="red_R" />
      </visual>
      <collision>
        <origin
          xyz="0 0 0"
          rpy="0 0 0" />
        <geometry>
          <mesh
            filename="package://${description_pkg}/meshes/m6/Link6_R.STL" />
        </geometry>
      </collision>
    </link>
    <joint
      name="Joint6_R"
      type="revolute">
      <xacro:marvin_joint_parameters key="joint6"/>

      <parent
        link="Link5_R" />
      <child
        link="Link6_R" />


    </joint>
    <link
      name="Link7_R">
      <xacro:marvin_link_inertial key="link7"/>
      <visual>
        <origin
          xyz="0 0 0"
          rpy="0 0 0" />
        <geometry>
          <mesh
            filename="package://${description_pkg}/meshes/m6/Link7_R.STL" />
        </geometry>
        <material name="green_R" />
      </visual>
      <collision>
        <origin
          xyz="0 0 0"
          rpy="0 0 0" />
        <geometry>
          <mesh
            filename="package://${description_pkg}/meshes/m6/Link7_R.STL" />
        </geometry>
      </collision>
    </link>
    <joint
      name="Joint7_R"
      type="revolute">
      <xacro:marvin_joint_parameters key="joint7"/>

      <parent
        link="Link6_R" />
      <child
        link="Link7_R" />


    </joint>
    <link name="flange_R"/>
    <joint name="joint_flange_R" type="fixed">
      <origin
        xyz="${marvin_kinematics['flange']['origin']['xyz']}"
        rpy="${marvin_kinematics['flange']['origin']['rpy']}"/>
      <parent link="Link7_R" />
      <child link="flange_R" />
    </joint>
  </xacro:macro>
</robot>
